<?xml version="1.0" encoding="utf-8"?>
<robot
  name="rx1_arm_description">
  <link
    name="torso_link">
    <inertial>
      <origin
        xyz="0 0 0"
        rpy="0 0 0" />
      <mass
        value="1.34289684822909" />
      <inertia
        ixx="0.0021852497910165"
        ixy="3.17878121171959E-10"
        ixz="-1.17585955037938E-06"
        iyy="0.00327147535237094"
        iyz="4.88930871512921E-06"
        izz="0.00232430919464608" />
    </inertial>
    <visual>
      <origin
        xyz="-0.009 0.6 0.075"
        rpy="0 0 0" />
      <geometry>
        <mesh
          filename="package://rx1_arm_description/meshes/torso_link.STL" />
      </geometry>
      <material
        name="">
        <color
          rgba="1.0 0.1 0.1 1" />
      </material>
    </visual>
    <collision>
      <origin
        xyz="-0.009 0.6 0.075"
        rpy="0 0 0" />
      <geometry>
        <mesh
          filename="package://rx1_arm_description/meshes/torso_link.STL" />
      </geometry>
    </collision>
  </link>
  <link
    name="left_shoulder_link">
    <inertial>
      <origin
        xyz="0 0 0"
        rpy="0 0 0" />
      <mass
        value="0.288652258668412" />
      <inertia
        ixx="0.000234306504757691"
        ixy="6.23188375486991E-11"
        ixz="2.51948775434514E-10"
        iyy="0.000298837549514291"
        iyz="-2.52641885619247E-07"
        izz="0.000256307384405807" />
    </inertial>
    <visual>
      <origin
        xyz="-0.025 0.025 0"
        rpy="0 0 0" />
      <geometry>
        <mesh
          filename="package://rx1_arm_description/meshes/left_shoulder_link.STL" />
      </geometry>
      <material
        name="">
        <color
          rgba="0.627450980392157 0.627450980392157 0.627450980392157 1" />
      </material>
    </visual>
    <collision>
      <origin
        xyz="-0.025 0.025 0"
        rpy="0 0 0" />
      <geometry>
        <mesh
          filename="package://rx1_arm_description/meshes/left_shoulder_link.STL" />
      </geometry>
    </collision>
  </link>
  <joint
    name="left_shoulder_pitch_joint"
    type="revolute">
    <origin
      xyz="0.178 -0.097 -0.0005"
      rpy="1.5708 0 1.0472" />
    <parent
      link="torso_link" />
    <child
      link="left_shoulder_link" />
    <axis
      xyz="0 0 1" />
    <limit
      effort="1000.0"
      lower="${-pi/2}"
      upper="${pi/2}"
      velocity="0.5" />
    <dynamics
      damping="0.1"
      friction="0.1"/>
  </joint>
  <link
    name="left_upper_arm_link">
    <inertial>
      <origin
        xyz="0 0 0"
        rpy="0 0 0" />
      <mass
        value="0.283657187889463" />
      <inertia
        ixx="0.000345847189916072"
        ixy="7.7801725061108E-06"
        ixz="-1.66430316737486E-06"
        iyy="0.000109479989909252"
        iyz="-8.09234354553956E-07"
        izz="0.000361901057222866" />
    </inertial>
    <visual>
      <origin
        xyz="-0.05 0.05 0"
        rpy="0 0 0" />
      <geometry>
        <mesh
          filename="package://rx1_arm_description/meshes/left_upper_arm_link.STL" />
      </geometry>
      <material
        name="">
        <color
          rgba="0.627450980392157 0.627450980392157 0.627450980392157 1" />
      </material>
    </visual>
    <collision>
      <origin
        xyz="-0.05 0.05 0"
        rpy="0 0 0" />
      <geometry>
        <mesh
          filename="package://rx1_arm_description/meshes/left_upper_arm_link.STL" />
      </geometry>
    </collision>
  </link>
  <joint
    name="left_shoulder_yaw_joint"
    type="revolute">
    <origin
      xyz="0 0.025 0.095"
      rpy="1.5708 0 -3.1416" />
    <parent
      link="left_shoulder_link" />
    <child
      link="left_upper_arm_link" />
    <axis
      xyz="0 0 1" />
    <limit
      effort="1000.0"
      lower="${-pi-1.2217}"
      upper="-1.2217"
      velocity="0.5" />
    <dynamics
      damping="0.1"
      friction="0.1"/>
  </joint>
  <link
    name="left_elbow_base_link">
    <inertial>
      <origin
        xyz="0 0 0"
        rpy="0 0 0" />
      <mass
        value="0.293645502053592" />
      <inertia
        ixx="0.000191111221894673"
        ixy="9.45073347943987E-07"
        ixz="6.94481242792893E-06"
        iyy="0.000205123311133165"
        iyz="-9.68513388538593E-06"
        izz="0.000127099474277" />
    </inertial>
    <visual>
      <origin
        xyz="-0.05 0.05 -0.02"
        rpy="0 0 0" />
      <geometry>
        <mesh
          filename="package://rx1_arm_description/meshes/left_elbow_base_link.STL" />
      </geometry>
      <material
        name="">
        <color
          rgba="0.0980392156862745 0.0980392156862745 0.0980392156862745 1" />
      </material>
    </visual>
    <collision>
      <origin
        xyz="-0.05 0.05 -0.02"
        rpy="0 0 0" />
      <geometry>
        <mesh
          filename="package://rx1_arm_description/meshes/left_elbow_base_link.STL" />
      </geometry>
    </collision>
  </link>
  <joint
    name="left_shoulder_roll_joint"
    type="revolute">
    <origin
      xyz="0.0235 -0.135 -0.037"
      rpy="-1.5708 0 0.17453" />
    <parent
      link="left_upper_arm_link" />
    <child
      link="left_elbow_base_link" />
    <axis
      xyz="0 0 1" />
    <limit
      effort="1000.0"
      lower="${-pi/2}"
      upper="${pi/2}"
      velocity="0.5" />
    <dynamics
      damping="0.1"
      friction="0.1"/>
  </joint>
  <link
    name="left_forearm_link">
    <inertial>
      <origin
        xyz="0 0 0"
        rpy="0 0 0" />
      <mass
        value="0.159937221118175" />
      <inertia
        ixx="6.46854761819896E-05"
        ixy="8.07077989814206E-06"
        ixz="-2.44590352387659E-06"
        iyy="7.98080919568964E-05"
        iyz="2.15312738879161E-07"
        izz="0.000104932736677374" />
    </inertial>
    <visual>
      <origin
        xyz="-0.05 0.05 -0.02"
        rpy="0 0 0" />
      <geometry>
        <mesh
          filename="package://rx1_arm_description/meshes/left_forearm_link.STL" />
      </geometry>
      <material
        name="">
        <color
          rgba="0.701960784313725 0.701960784313725 0.701960784313725 1" />
      </material>
    </visual>
    <collision>
      <origin
        xyz="-0.05 0.05 -0.02"
        rpy="0 0 0" />
      <geometry>
        <mesh
          filename="package://rx1_arm_description/meshes/left_forearm_link.STL" />
      </geometry>
    </collision>
  </link>
  <joint
    name="left_elbow_joint"
    type="revolute">
    <origin
      xyz="-0.02 0 -0.225"
      rpy="-1.5708 ${-pi/2} -1.5708" />
    <parent
      link="left_elbow_base_link" />
    <child
      link="left_forearm_link" />
    <axis
      xyz="0 0 1" />
    <limit
      effort="1000.0"
      lower="${-pi/2}"
      upper="${pi/2}"
      velocity="0.5" />
    <dynamics
      damping="0.1"
      friction="0.1"/>
  </joint>
  <link
    name="left_forearm_pitch_link">
    <inertial>
      <origin
        xyz="0 0 0"
        rpy="0 0 0" />
      <mass
        value="0.119336418277092" />
      <inertia
        ixx="5.51743771905473E-05"
        ixy="3.92785306054048E-06"
        ixz="1.48441169125576E-06"
        iyy="6.48124552274375E-05"
        iyz="-1.1439972691833E-06"
        izz="7.22735369278745E-05" />
    </inertial>
    <visual>
      <origin
        xyz="0.035 0 -0.0125"
        rpy="0 0 0" />
      <geometry>
        <mesh
          filename="package://rx1_arm_description/meshes/left_forearm_pitch_link.STL" />
      </geometry>
      <material
        name="">
        <color
          rgba="0.0980392156862745 0.0980392156862745 0.0980392156862745 1" />
      </material>
    </visual>
    <collision>
      <origin
        xyz="0.035 0 -0.0125"
        rpy="0 0 0" />
      <geometry>
        <mesh
          filename="package://rx1_arm_description/meshes/left_forearm_pitch_link.STL" />
      </geometry>
    </collision>
  </link>
  <joint
    name="left_forearm_roll_joint"
    type="revolute">
    <origin
      xyz="-0.09 0 0.0155"
      rpy="0 0 3.1416" />
    <parent
      link="left_forearm_link" />
    <child
      link="left_forearm_pitch_link" />
    <axis
      xyz="1 0 0" />
    <limit
      effort="1000.0"
      lower="${-pi/2}"
      upper="${pi/2}"
      velocity="0.5" />
    <dynamics
      damping="0.1"
      friction="0.1"/>
  </joint>
  <link
    name="left_forearm_roll_link">
    <inertial>
      <origin
        xyz="-4.59996454264533E-05 -0.0106209900521888 0.0122467252479195"
        rpy="0 0 0" />
      <mass
        value="0.0744709825981583" />
      <inertia
        ixx="2.47652817135528E-05"
        ixy="7.93488038079891E-11"
        ixz="2.30729859217063E-10"
        iyy="1.9982959754195E-05"
        iyz="-8.59225034352214E-07"
        izz="3.07032565952786E-05" />
    </inertial>
    <visual>
      <origin
        xyz="0 0 -0.0125"
        rpy="0 0 0" />
      <geometry>
        <mesh
          filename="package://rx1_arm_description/meshes/left_forearm_roll_link.STL" />
      </geometry>
      <material
        name="">
        <color
          rgba="0.0980392156862745 0.0980392156862745 0.0980392156862745 1" />
      </material>
    </visual>
    <collision>
      <origin
        xyz="0 0 0"
        rpy="0 0 0" />
      <geometry>
        <mesh
          filename="package://rx1_arm_description/meshes/left_forearm_roll_link.STL" />
      </geometry>
    </collision>
  </link>
  <joint
    name="left_forearm_pitch_joint"
    type="revolute">
    <origin
      xyz="0.175 0 0.002"
      rpy="${pi} 1.5708 0" />
    <parent
      link="left_forearm_pitch_link" />
    <child
      link="left_forearm_roll_link" />
    <axis
      xyz="1 0 0" />
    <limit
      effort="1000.0"
      lower="${-pi/4}"
      upper="${pi/4}"
      velocity="0.5" />
    <dynamics
      damping="0.1"
      friction="0.1"/>
  </joint>



  <link
    name="right_shoulder_link">
    <inertial>
      <origin
        xyz="0 0 0"
        rpy="0 0 0" />
      <mass
        value="0.241078385573073" />
      <inertia
        ixx="0.000212462211234769"
        ixy="-1.39271526133161E-06"
        ixz="2.13127282918627E-10"
        iyy="0.000268277812827925"
        iyz="3.67630787278507E-11"
        izz="0.000240397238836167" />
    </inertial>
    <visual>
      <origin
        xyz="-0.0498 0.050 0.0185"
        rpy="0 0 0" />
      <geometry>
        <mesh
          filename="package://rx1_arm_description/meshes/right_shoulder_link.STL" />
      </geometry>
      <material name="">
        <color rgba="0.627450980392157 0.627450980392157 0.627450980392157 1" />
      </material>
    </visual>
    <collision>
      <origin
        xyz="-0.0498 0.050 0.0185"
        rpy="0 0 0" />
      <geometry>
        <mesh
          filename="package://rx1_arm_description/meshes/right_shoulder_link.STL" />
      </geometry>
    </collision>
  </link>
  <joint
    name="right_shoulder_pitch_joint"
    type="revolute">
    <origin
      xyz="-0.154 -0.0825 -0.0005"
      rpy="1.5708 0 -1.0472" />
    <parent
      link="torso_link" />
    <child
      link="right_shoulder_link" />
    <axis
      xyz="0 0 1" />
    <limit
      effort="1000.0"
      lower="${-pi/2}"
      upper="${pi/2}"
      velocity="0.5" />
    <dynamics
      damping="0.1"
      friction="0.1"/>
  </joint>
  <link
    name="right_upper_arm_link">
    <inertial>
      <origin
        xyz="0 0 0"
        rpy="0 0 0" />
      <mass
        value="0.276361335782325" />
      <inertia
        ixx="0.000340747739679373"
        ixy="3.35254394472819E-05"
        ixz="-1.77533536363304E-06"
        iyy="0.000113409462339347"
        iyz="4.57924276177876E-07"
        izz="0.000361341150702589" />
    </inertial>
    <visual>
      <origin
        xyz="-0.05 0.05 0"
        rpy="0 0 0" />
      <geometry>
        <mesh
          filename="package://rx1_arm_description/meshes/right_upper_arm_link.STL" />
      </geometry>
      <material
        name="">
        <color
          rgba="0.627450980392157 0.627450980392157 0.627450980392157 1" />
      </material>
    </visual>
    <collision>
      <origin
        xyz="-0.05 0.05 0"
        rpy="0 0 0" />
      <geometry>
        <mesh
          filename="package://rx1_arm_description/meshes/right_upper_arm_link.STL" />
      </geometry>
    </collision>
  </link>
  <joint
    name="right_shoulder_yaw_joint"
    type="revolute">
    <origin
      xyz="0 0.025 0.1213"
      rpy="-1.5708 1.0472 0.024932" />
    <parent
      link="right_shoulder_link" />
    <child
      link="right_upper_arm_link" />
    <axis
      xyz="0 0 1" />
    <limit
      effort="1000.0"
      lower="${pi}"
      upper="0"
      velocity="0.5" />
    <dynamics
      damping="0.1"
      friction="0.1"/>
    </joint>
  <link
    name="right_elbow_base_link">
    <inertial>
      <origin
        xyz="0 0 0"
        rpy="0 0 0" />
      <mass
        value="0.294022438354874" />
      <inertia
        ixx="0.000191113243166891"
        ixy="-7.11355737126455E-07"
        ixz="-7.17855383108209E-06"
        iyy="0.000215190065240535"
        iyz="-9.68491463451935E-06"
        izz="0.000117048837218324" />
    </inertial>
    <visual>
      <origin
        xyz="-0.05 0.05 -0.02"
        rpy="0 0 0" />
      <geometry>
        <mesh
          filename="package://rx1_arm_description/meshes/right_elbow_base_link.STL" />
      </geometry>
      <material
        name="">
        <color
          rgba="0.0980392156862745 0.0980392156862745 0.0980392156862745 1" />
      </material>
    </visual>
    <collision>
      <origin
        xyz="-0.05 0.05 -0.02"
        rpy="0 0 0" />
      <geometry>
        <mesh
          filename="package://rx1_arm_description/meshes/right_elbow_base_link.STL" />
      </geometry>
    </collision>
  </link>
  <joint
    name="right_shoulder_roll_joint"
    type="revolute">
    <origin
      xyz="0 0.135 -0.037"
      rpy="-1.5708 0 -3.1416" />
    <parent
      link="right_upper_arm_link" />
    <child
      link="right_elbow_base_link" />
    <axis
      xyz="0 0 1" />
    <limit
      effort="1000.0"
      lower="${-pi/2}"
      upper="${pi/2}"
      velocity="0.5" />
    <dynamics
      damping="0.1"
      friction="0.1"/>
  </joint>
  <link
    name="right_forearm_link">
    <inertial>
      <origin
        xyz="0 0 0"
        rpy="0 0 0" />
      <mass
        value="0.159937357061386" />
      <inertia
        ixx="6.46855176197894E-05"
        ixy="8.07077158024439E-06"
        ixz="2.44576568345528E-06"
        iyy="7.98080909205345E-05"
        iyz="-2.14722205358431E-07"
        izz="0.000104932776106174" />
    </inertial>
    <visual>
      <origin
        xyz="-0.05 0.05 0.02"
        rpy="0 0 0" />
      <geometry>
        <mesh
          filename="package://rx1_arm_description/meshes/right_forearm_link.STL" />
      </geometry>
      <material
        name="">
        <color
          rgba="0.701960784313725 0.701960784313725 0.701960784313725 1" />
      </material>
    </visual>
    <collision>
      <origin
        xyz="-0.05 0.05 0.02"
        rpy="0 0 0" />
      <geometry>
        <mesh
          filename="package://rx1_arm_description/meshes/right_forearm_link.STL" />
      </geometry>
    </collision>
  </link>
  <joint
    name="right_elbow_joint"
    type="revolute">
    <origin
      xyz="0.02 0 -0.225"
      rpy="-1.5708 ${-pi/2} -1.5708" />
    <parent
      link="right_elbow_base_link" />
    <child
      link="right_forearm_link" />
    <axis
      xyz="0 0 1" />
    <limit
      effort="1000.0"
      lower="${pi/2}"
      upper="${-pi/2}"
      velocity="0.5" />
    <dynamics
      damping="0.1"
      friction="0.1"/>
  </joint>
  <link
    name="right_forearm_pitch_link">
    <inertial>
      <origin
        xyz="0 0 0"
        rpy="0 0 0" />
      <mass
        value="0.119336447852501" />
      <inertia
        ixx="5.5174396893135E-05"
        ixy="3.92794939138855E-06"
        ixz="-1.4841399716682E-06"
        iyy="6.48124631446172E-05"
        iyz="1.14403477595069E-06"
        izz="7.22735525494739E-05" />
    </inertial>
    <visual>
      <origin
        xyz="0.035 0 0.0125"
        rpy="0 0 0" />
      <geometry>
        <mesh
          filename="package://rx1_arm_description/meshes/right_forearm_pitch_link.STL" />
      </geometry>
      <material
        name="">
        <color
          rgba="0.0980392156862745 0.0980392156862745 0.0980392156862745 1" />
      </material>
    </visual>
    <collision>
      <origin
        xyz="0 0 0"
        rpy="0 0 0" />
      <geometry>
        <mesh
          filename="package://rx1_arm_description/meshes/right_forearm_pitch_link.STL" />
      </geometry>
    </collision>
  </link>
  <joint
    name="right_forearm_roll_joint"
    type="revolute">
    <origin
      xyz="-0.09 0 -0.0155"
      rpy="0 0 -3.1416" />
    <parent
      link="right_forearm_link" />
    <child
      link="right_forearm_pitch_link" />
    <axis
      xyz="1 0 0" />
    <limit
      effort="1000.0"
      lower="${-pi/2}"
      upper="${pi/2}"
      velocity="0.5" />
    <dynamics
      damping="0.1"
      friction="0.1"/>
  </joint>
  <link
    name="right_forearm_roll_link">
    <inertial>
      <origin
        xyz="0 0 0"
        rpy="0 0 0" />
      <mass
        value="0.076585392847017" />
      <inertia
        ixx="2.5241632736512E-05"
        ixy="1.81438863760255E-10"
        ixz="4.43189908448262E-11"
        iyy="2.05016068240719E-05"
        iyz="8.63779845937977E-07"
        izz="3.16946939480451E-05" />
    </inertial>
    <visual>
      <origin
        xyz="0 0 0.02"
        rpy="0 0 0" />
      <geometry>
        <mesh
          filename="package://rx1_arm_description/meshes/right_forearm_roll_link.STL" />
      </geometry>
      <material
        name="">
        <color
          rgba="0.0980392156862745 0.0980392156862745 0.0980392156862745 1" />
      </material>
    </visual>
    <collision>
      <origin
        xyz="0 0 0.02"
        rpy="0 0 0" />
      <geometry>
        <mesh
          filename="package://rx1_arm_description/meshes/right_forearm_roll_link.STL" />
      </geometry>
    </collision>
  </link>
  <joint
    name="right_forearm_pitch_joint"
    type="revolute">
    <origin
      xyz="0.175 0 -0.002"
      rpy="-1.5708 -1.5708 0" />
    <parent
      link="right_forearm_pitch_link" />
    <child
      link="right_forearm_roll_link" />
    <axis
      xyz="1 0 0" />
    <limit
      effort="1000.0"
      lower="${-pi/4}"
      upper="${pi/4}"
      velocity="0.5" />
    <dynamics
      damping="0.1"
      friction="0.1"/>
  </joint>
</robot>
